<mujoco model="30mm_one_segment">
    <!-- <compiler angle="radian" eulerseq="XYZ" /> --> <!--eulerseq="xyz"→ euler="a b c" 같은 오일러 각을 x → y → z 순서로, 축이 매 단계 회전과 함께 따라가는 “내재(intrinsic)” 방식으로 적용한다는 뜻, 소문자 = intrinsic / 대문자 = extrinsic-->
    <!-- <include file="scene.xml"/> 배경, 바닥 등 추가 가능 -->
    <!-- <extension>
        <plugin plugin="mujoco.elasticity.cable"/>
    </extension> -->
    <size memory="128M"/>

    <asset>
        <mesh name="mesh_component2" file="meshes/mesh_component2.stl" scale="0.001 0.001 0.001" /> <!-- The mesh file for the component -->
    </asset>
    <worldbody>
        <!-- <light directional="true" pos="-0.5 0.5 3" dir="0 0 -1" /> A light source -->
        <!-- <geom pos="0 0 -0.01" size="1 1 1" type="plane" rgba="1 0.83 0.61 0.5" /> A ground plane -->

        <body name="comp_root" pos="0 0 0" quat="1 0 0 0">
            <geom name="geom_comp_root" type="mesh" mesh="mesh_component2" pos="0 0 0"/>
            <inertial mass="0.034962578305385045" pos="-7.472585541467528e-08 7.901881324749933e-09 0.00013813391178014084" fullinertia="3.055182113221844e-06 2.848652002682884e-06 5.213750324900917e-06 -4.694970745810055e-12 -1.2612174129223041e-11 1.8838018378797825e-12" />
            
            <body name="comp_1" pos="0 0 0.015" quat="0.70710678 0 0 -0.70710678">
                <joint name="rotation_1" type="hinge" axis="1 0 0" pos="0.01794 0 -0.0075" /> <!--joint axis: 이 조인트가 어느 방향으로 움직이는지, pos: 조인트의 앵커(회전/이동이 일어나는 점) 위치-->
                <geom name="geom_comp_1" type="mesh" mesh="mesh_component2" pos="0 0 0" quat="1 0 0 0"/>
                <inertial mass="0.034962578305385045" pos="-7.472585541454448e-08 7.901881324746635e-09 0.00013813391178014496" fullinertia="3.0551821132218284e-06 2.8486520026829268e-06 5.213750324900907e-06 -4.694970745810085e-12 -1.2612174121400085e-11 1.8838018376833885e-12" />
                
                <body name="comp_2" pos="0 0 0.015" quat="0.70710678 0 0 0.70710678">
                    <joint name="rotation_2" type="hinge" axis="1 0 0" pos="0.01794 0 -0.0075" />
                    <geom name="geom_comp_2" type="mesh" mesh="mesh_component2" pos="0 0 0" quat="1 0 0 0"/>
                    <inertial mass="0.034962578305385045" pos="-7.472585541454448e-08 7.901881324746635e-09 0.00013813391178014273" fullinertia="3.0551821132218267e-06 2.84865200268293e-06 5.213750324900907e-06 -4.694970745810085e-12 -1.2612174121400085e-11 1.8838018376833877e-12" />
                    
                    <body name="comp_3" pos="0 0 0.015" quat="0.70710678 0 0 -0.70710678">
                        <joint name="rotation_3" type="hinge" axis="1 0 0" pos="0.01794 0 -0.0075" />
                        <geom name="geom_comp_3" type="mesh" mesh="mesh_component2" pos="0 0 0" quat="1 0 0 0"/>
                        <inertial mass="0.034962578305385045" pos="-7.47258554145445e-08 7.901881324746637e-09 0.00013813391178014273" fullinertia="3.0551821132218403e-06 2.84865200268293e-06 5.213750324900907e-06 -4.694970745810085e-12 -1.2612174121400085e-11 1.883801837683387e-12" />
                        
                        <body name="comp_4" pos="0 0 0.015" quat="0.70710678 0 0 0.70710678">
                            <joint name="rotation_4" type="hinge" axis="1 0 0" pos="0.01794 0 -0.0075" />
                            <geom name="geom_comp_4" type="mesh" mesh="mesh_component2" pos="0 0 0" quat="1 0 0 0"/>
                            <inertial mass="0.034962578305385045" pos="-7.472585541454448e-08 7.901881324015413e-09 0.00013813391178015038" fullinertia="3.055182113221813e-06 2.8486520026828874e-06 5.213750324900898e-06 -4.69497074581008e-12 -1.2612174121400061e-11 1.8838018335764905e-12" />
                            
                            <body name="comp_5" pos="0 0 0.015" quat="0.70710678 0 0 -0.70710678">
                                <joint name="rotation_5" type="hinge" axis="1 0 0" pos="0.01794 0 -0.0075" />
                                <geom name="geom_comp_5" type="mesh" mesh="mesh_component2" pos="0 0 0" quat="1 0 0 0"/>
                                <inertial mass="0.034962578305385045" pos="-7.472585541496629e-08 7.901881324746634e-09 0.0001381339117801356" fullinertia="3.0551821132218623e-06 2.8486520026829437e-06 5.213750324900904e-06 -4.694970745810083e-12 -1.261217412324965e-11 1.883801837683382e-12" />
                                
                                <body name="comp_6" pos="0 0 0.015" quat="0.70710678 0 0 0.70710678">
                                    <joint name="rotation_6" type="hinge" axis="1 0 0" pos="0.01794 0 -0.0075" />
                                    <geom name="geom_comp_6" type="mesh" mesh="mesh_component2" pos="0 0 0" quat="1 0 0 0"/>
                                    <inertial mass="0.034962578305385045" pos="-7.472585541454451e-08 7.901881323397079e-09 0.00013813391178015924" fullinertia="3.0551821132217047e-06 2.8486520026828886e-06 5.213750324900898e-06 -4.6949707458100755e-12 -1.261217412140013e-11 1.883801832570639e-12" />
                                    
                                    <body name="comp_7" pos="0 0 0.015" quat="0.70710678 0 0 -0.70710678">
                                        <joint name="rotation_7" type="hinge" axis="1 0 0" pos="0.01794 0 -0.0075" />
                                        <geom name="geom_comp_7" type="mesh" mesh="mesh_component2" pos="0 0 0" quat="1 0 0 0"/>
                                        <inertial mass="0.034962578305385045" pos="-7.472585541316211e-08 7.901881324746632e-09 0.00013813391178015339" fullinertia="3.0551821132217585e-06 2.8486520026828353e-06 5.213750324900921e-06 -4.6949707458100884e-12 -1.2612174111020612e-11 1.883801837683386e-12" />
                                                <!-- ================= SEGMENT 2 ================= -->
                                        <body name="seg2_base" pos="0 0 0.005">
                                            <body name="seg2_v1" pos="0 0 0.0075">
                                                <geom name="seg2_v1_geom" fromto="0 0 0  0 0 0.012"/>
                                                <joint name="seg2_j1_pitch" type="hinge" axis="1 0 0"/>

                                                <body name="seg2_v2" pos="0 0 0.012">
                                                    <geom name="seg2_v2_geom" fromto="0 0 0  0 0 0.012"/>
                                                    <joint name="seg2_j2_yaw" type="hinge" axis="0 1 0"/>

                                                    <body name="seg2_v3" pos="0 0 0.012">
                                                        <geom name="seg2_v3_geom" fromto="0 0 0  0 0 0.012"/>
                                                        <joint name="seg2_j3_pitch" type="hinge" axis="1 0 0"/>

                                                        <body name="seg2_v4" pos="0 0 0.012">
                                                            <geom name="seg2_v4_geom" fromto="0 0 0  0 0 0.012"/>
                                                            <joint name="seg2_j4_yaw" type="hinge" axis="0 1 0"/>

                                                            <body name="seg2_v5" pos="0 0 0.012">
                                                                <geom name="seg2_v5_geom" fromto="0 0 0  0 0 0.012"/>
                                                                <joint name="seg2_j5_pitch" type="hinge" axis="1 0 0"/>

                                                                <body name="seg2_v6" pos="0 0 0.012">
                                                                    <geom name="seg2_v6_geom" fromto="0 0 0  0 0 0.012"/>
                                                                    <joint name="seg2_j6_yaw" type="hinge" axis="0 1 0"/>

                                                                    <body name="seg2_v7" pos="0 0 0.012">
                                                                        <geom name="seg2_v7_geom" fromto="0 0 0  0 0 0.012"/>
                                                                        <joint name="seg2_j7_pitch" type="hinge" axis="1 0 0"/>

                                                                        <body name="seg2_v8" pos="0 0 0.012">
                                                                            <geom name="seg2_v8_geom" fromto="0 0 0  0 0 0.012"/>
                                                                            <joint name="seg2_j8_yaw" type="hinge" axis="0 1 0"/>

                                                                            <body name="seg2_v9" pos="0 0 0.012">
                                                                                <geom name="seg2_v9_geom" fromto="0 0 0  0 0 0.012"/>
                                                                                    <body name="seg2_v10" pos="0 0 0.012">
                                                                                    <geom name="seg2_v10_geom" fromto="0 0 0  0 0 0.012"/>


                                                                                <!-- ================= SEGMENT 3 ================= -->

                                                                                    <body name="seg3_base" pos="0 0 0.005">
                                                                                        <body name="seg3_v1" pos="0 0 0.012">
                                                                                            <geom name="seg3_v1_geom" fromto="0 0 0  0 0 0.012"/>
                                                                                            <joint name="seg3_j1_pitch" type="hinge" axis="1 0 0"/>

                                                                                            <body name="seg3_v2" pos="0 0 0.012">
                                                                                                <geom name="seg3_v2_geom" fromto="0 0 0  0 0 0.012"/>
                                                                                                <joint name="seg3_j2_yaw" type="hinge" axis="0 1 0"/>

                                                                                                <body name="seg3_v3" pos="0 0 0.012">
                                                                                                    <geom name="seg3_v3_geom" fromto="0 0 0  0 0 0.012"/>
                                                                                                    <joint name="seg3_j3_pitch" type="hinge" axis="1 0 0"/>

                                                                                                    <body name="seg3_v4" pos="0 0 0.012">
                                                                                                        <geom name="seg3_v4_geom" fromto="0 0 0  0 0 0.012"/>
                                                                                                        <joint name="seg3_j4_yaw" type="hinge" axis="0 1 0"/>

                                                                                                        <body name="seg3_v5" pos="0 0 0.012">
                                                                                                            <geom name="seg3_v5_geom" fromto="0 0 0  0 0 0.012"/>
                                                                                                            <joint name="seg3_j5_pitch" type="hinge" axis="1 0 0"/>

                                                                                                            <body name="seg3_v6" pos="0 0 0.012">
                                                                                                                <geom name="seg3_v6_geom" fromto="0 0 0  0 0 0.012"/>
                                                                                                                <joint name="seg3_j6_yaw" type="hinge" axis="0 1 0"/>

                                                                                                                <body name="seg3_v7" pos="0 0 0.012">
                                                                                                                    <geom name="seg3_v7_geom" fromto="0 0 0  0 0 0.012"/>
                                                                                                                    <joint name="seg3_j7_pitch" type="hinge" axis="1 0 0"/>

                                                                                                                    <body name="seg3_v8" pos="0 0 0.012">
                                                                                                                        <geom name="seg3_v8_geom" fromto="0 0 0  0 0 0.012"/>
                                                                                                                        <joint name="seg3_j8_yaw" type="hinge" axis="0 1 0"/>

                                                                                                                        <body name="seg3_v9" pos="0 0 0.012">
                                                                                                                            <geom name="seg3_v9_geom" fromto="0 0 0  0 0 0.012"/>
                                                                                                                            <body name="seg3_v10" pos="0 0 0.012">
                                                                                                                                <geom name="seg3_v10_geom" fromto="0 0 0  0 0 0.012"/>
                                                                                                                            </body>
                                                                                                                        </body>
                                                                                                                    </body>
                                                                                                                </body>
                                                                                                            </body>
                                                                                                        </body>
                                                                                                    </body>
                                                                                                </body>
                                                                                            </body>
                                                                                        </body>
                                                                                    </body>
                                                                                </body>
                                                                            </body>
                                                                        </body>
                                                                    </body>
                                                                </body>
                                                            </body>
                                                        </body>
                                                    </body>
                                                </body>
                                            </body>
                                        </body>
                                    </body>
                                </body>
                            </body>
                        </body>
                    </body>
                </body>
            </body>
        </body>
    </worldbody>

</mujoco>



    <!-- <position name="u_seg2_j1" joint="seg2_j1_pitch" kp="200" ctrlrange="-0.5 0.5"/>
    <position name="u_seg2_j2" joint="seg2_j2_yaw"   kp="200" ctrlrange="-0.5 0.5"/>
    
    <position name="u_seg3_j1" joint="seg3_j1_pitch" kp="200" ctrlrange="-0.5 0.5"/>
    <position name="u_seg3_j2" joint="seg3_j2_yaw"   kp="200" ctrlrange="-0.5 0.5"/> -->