<mujoco model="30mm_one_segment">
    <include file="scene.xml"/>
    <compiler angle="radian" eulerseq="XYZ" />
    <asset>
        <!-- <mesh name="30mm_og-v1" file="meshes/30mm_og-v1.stl" scale="0.001 0.001 0.001" /> -->
        <mesh name="mesh_component2" file="meshes/mesh_component2.stl" scale="0.001 0.001 0.001" />\ // The mesh file for the component
    </asset>
    <worldbody>
        <light directional="true" pos="-0.5 0.5 3" dir="0 0 -1" /> // A light source
        <geom pos="0 0 -0.01" size="1 1 1" type="plane" rgba="1 0.83 0.61 0.5" /> // A ground plane
        <!-- <body name="30mm_og-v1" pos="0.0 0.0 0.0" euler="0.0 -0.0 0.0">
            <geom name="30mm_og-v1_geom" type="mesh" mesh="30mm_og-v1" pos="0 0 0" euler="0 0 0" />
            <inertial mass="0.020186372964312565" pos="-2.028876088583636e-09 -2.2527130368459546e-10 0.015102317839665105" fullinertia="2.132115275741312e-06 2.0366456276047753e-06 3.7985387703791073e-06 2.083594284754371e-11 -1.7720432626041117e-13 -2.7284120286848526e-14" />
        </body> -->

        <body name="comp_root" pos="0.0 0.0 0.0" euler="0.0 0.0 0.0">
            <geom name="geom_comp_root" type="mesh" mesh="mesh_component2" pos="0 0 0" euler="0 0 0" />
            <inertial mass="0.034962578305385045" pos="-7.472585541467528e-08 7.901881324749933e-09 0.00013813391178014084" fullinertia="3.055182113221844e-06 2.848652002682884e-06 5.213750324900917e-06 -4.694970745810055e-12 -1.2612174129223041e-11 1.8838018378797825e-12" />
            
            <body name="comp_1" pos="1.1102230246251566e-18 -1.7763568394002505e-17 0.015" euler="-6.123233995736765e-17 -4.930380657631328e-32 -1.5707963267948968">
                <joint name="rotation-1" type="hinge" axis="1 2.220446049250335e-16 9.459870649918561e-16" pos="0.01793999999999997 3.332499737410193e-18 -0.007499999999999979" />
                <geom name="geom_comp_1" type="mesh" mesh="mesh_component2" pos="0 0 0" euler="0 0 0" />
                <inertial mass="0.034962578305385045" pos="-7.472585541454448e-08 7.901881324746635e-09 0.00013813391178014496" fullinertia="3.0551821132218284e-06 2.8486520026829268e-06 5.213750324900907e-06 -4.694970745810085e-12 -1.2612174121400085e-11 1.8838018376833885e-12" />
                
                <body name="comp_2" pos="-3.1435916855538975e-17 1.1286600475013078e-17 0.015" euler="6.123233995736771e-17 2.711709361697241e-31 1.5707963267948963">
                    <joint name="rotation-2" type="hinge" axis="1 5.665538897648013e-16 1.0072194049492237e-15" pos="-2.1736177992490477e-17 0.017940000000000077 -0.02249999999999998" />
                    <geom name="geom_comp_2" type="mesh" mesh="mesh_component2" pos="0 0 0" euler="0 0 0" />
                    <inertial mass="0.034962578305385045" pos="-7.472585541454448e-08 7.901881324746635e-09 0.00013813391178014273" fullinertia="3.0551821132218267e-06 2.84865200268293e-06 5.213750324900907e-06 -4.694970745810085e-12 -1.2612174121400085e-11 1.8838018376833877e-12" />
                    
                    <body name="comp_3" pos="-1.6982327090063196e-17 -9.821064446816138e-17 0.015" euler="-6.123233995736765e-17 -2.465190328815674e-32 -1.5707963267948963">
                        <joint name="rotation-3" type="hinge" axis="1 2.220446049250335e-16 1.0072194049492235e-15" pos="0.01793999999999989 -2.4999871341683295e-18 -0.037499999999999985" />
                        <geom name="geom_comp_3" type="mesh" mesh="mesh_component2" pos="0 0 0" euler="0 0 0" />
                        <inertial mass="0.034962578305385045" pos="-7.47258554145445e-08 7.901881324746637e-09 0.00013813391178014273" fullinertia="3.0551821132218403e-06 2.84865200268293e-06 5.213750324900907e-06 -4.694970745810085e-12 -1.2612174121400085e-11 1.883801837683387e-12" />
                        
                        <body name="comp_4" pos="-0.0006536680706074506 1.0328876273380923e-16 0.015" euler="-0.08726646259971796 7.395570986447022e-32 1.5707963267948963">
                            <joint name="rotation-4" type="hinge" axis="1 5.537244810286261e-16 1.1173641548954435e-15" pos="-1.1934632759344851e-16 0.02179374130741077 -0.05076518738923551" />
                            <geom name="geom_comp_4" type="mesh" mesh="mesh_component2" pos="0 0 0" euler="0 0 0" />
                            <inertial mass="0.034962578305385045" pos="-7.472585541454448e-08 7.901881324015413e-09 0.00013813391178015038" fullinertia="3.055182113221813e-06 2.8486520026828874e-06 5.213750324900898e-06 -4.69497074581008e-12 -1.2612174121400061e-11 1.8838018335764905e-12" />
                            
                            <body name="comp_5" pos="-1.6857852183800285e-17 -9.769962616701378e-17 0.015" euler="-6.123233995736664e-17 -0.0 -1.5707963267948963">
                                <joint name="rotation-5" type="hinge" axis="1 2.0921521031216163e-16 2.2996038091804838e-07" pos="0.013949724460121028 -9.693769851317469e-17 -0.06889233543902153" />
                                <geom name="geom_comp_5" type="mesh" mesh="mesh_component2" pos="0 0 0" euler="0 0 0" />
                                <inertial mass="0.034962578305385045" pos="-7.472585541496629e-08 7.901881324746634e-09 0.0001381339117801356" fullinertia="3.0551821132218623e-06 2.8486520026829437e-06 5.213750324900904e-06 -4.694970745810083e-12 -1.261217412324965e-11 1.883801837683382e-12" />
                                
                                <body name="comp_6" pos="-7.216449660063518e-18 9.983601960961502e-17 0.015" euler="1.2490009027033014e-16 -1.7256332301709719e-31 1.5707963267948963">
                                    <joint name="rotation-6" type="hinge" axis="1 5.537244810286261e-16 1.1785964948528107e-15" pos="-2.1212196494271593e-16 0.021793741307410876 -0.08076518738923547" />
                                    <geom name="geom_comp_6" type="mesh" mesh="mesh_component2" pos="0 0 0" euler="0 0 0" />
                                    <inertial mass="0.034962578305385045" pos="-7.472585541454451e-08 7.901881323397079e-09 0.00013813391178015924" fullinertia="3.0551821132217047e-06 2.8486520026828886e-06 5.213750324900898e-06 -4.6949707458100755e-12 -1.261217412140013e-11 1.883801832570639e-12" />
                                    
                                    <body name="comp_7" pos="-1.6857852183800538e-17 -9.880984919163893e-17 0.015" euler="-6.123233995736802e-17 -0.0 -1.5707963267948963">
                                        <joint name="rotation-7" type="hinge" axis="1 2.0921519623114963e-16 2.2996038098743732e-07" pos="0.013949724460120938 -1.8768488307123973e-16 -0.09889233543902169" />
                                        <geom name="geom_comp_7" type="mesh" mesh="mesh_component2" pos="0 0 0" euler="0 0 0" />
                                        <inertial mass="0.034962578305385045" pos="-7.472585541316211e-08 7.901881324746632e-09 0.00013813391178015339" fullinertia="3.0551821132217585e-06 2.8486520026828353e-06 5.213750324900921e-06 -4.6949707458100884e-12 -1.2612174111020612e-11 1.883801837683386e-12" />
                                    </body>
                                </body>
                            </body>
                        </body>
                    </body>
                </body>
            </body>
        </body>
    </worldbody>
</mujoco>
